2024-02-28 15:09:57,264 - INFO - Socket error: [WinError 10038] An operation was attempted on something that is not a socket
2024-02-28 15:09:57,289 - INFO - connection closed
2024-02-28 15:10:24,323 - INFO - Error sending data at handle.py/feed_server_data, exp: Task <Task pending name='Task-10' coro=<feed_server_data_to_page() running at C:\Users\7862s\Desktop\remotezone\webpage\handle.py:240> cb=[_run_until_complete_cb() at C:\Program Files\WindowsApps\PythonSoftwareFoundation.Python.3.11_3.11.2288.0_x64__qbz5n2kfra8p0\Lib\asyncio\base_events.py:181]> got Future <Future pending cb=[shield.<locals>._outer_done_callback() at C:\Program Files\WindowsApps\PythonSoftwareFoundation.Python.3.11_3.11.2288.0_x64__qbz5n2kfra8p0\Lib\asyncio\tasks.py:908]> attached to a different loop
2024-02-28 15:10:32,046 - INFO - Error sending data at handle.py/feed_server_data, exp: Task <Task pending name='Task-13' coro=<feed_server_data_to_page() running at C:\Users\7862s\Desktop\remotezone\webpage\handle.py:240> cb=[_run_until_complete_cb() at C:\Program Files\WindowsApps\PythonSoftwareFoundation.Python.3.11_3.11.2288.0_x64__qbz5n2kfra8p0\Lib\asyncio\base_events.py:181]> got Future <Future pending cb=[shield.<locals>._outer_done_callback() at C:\Program Files\WindowsApps\PythonSoftwareFoundation.Python.3.11_3.11.2288.0_x64__qbz5n2kfra8p0\Lib\asyncio\tasks.py:908]> attached to a different loop
2024-02-28 15:11:15,158 - INFO - Error sending active status at manager_requests.py/signal_active_status exp :  [WinError 10060] A connection attempt failed because the connected party did not properly respond after a period of time, or established connection failed because connected host has failed to respond
